This is an error I recieve after starting the server and trying to complete the signup page and create a new user. On the browser it gives a Internal 500 error.

Exception in ASGI application
Traceback (most recent call last):
  File "C:\Users\llyn0\Desktop\Coding projects\WebDev2FinalProject\.venv312\Lib\site-packages\uvicorn\protocols\http\httptools_impl.py", line 409, in run_asgi
    result = await app(  # type: ignore[func-returns-value]
             ^^^^^^^^^^^^^^^^^^^^^^^^^^^^^^^^^^^^^^^^^^^^^^
  File "C:\Users\llyn0\Desktop\Coding projects\WebDev2FinalProject\.venv312\Lib\site-packages\uvicorn\middleware\proxy_headers.py", line 60, in __call__ 
    return await self.app(scope, receive, send)
           ^^^^^^^^^^^^^^^^^^^^^^^^^^^^^^^^^^^^
  File "C:\Users\llyn0\Desktop\Coding projects\WebDev2FinalProject\.venv312\Lib\site-packages\fastapi\applications.py", line 1133, in __call__
    await super().__call__(scope, receive, send)
  File "C:\Users\llyn0\Desktop\Coding projects\WebDev2FinalProject\.venv312\Lib\site-packages\starlette\applications.py", line 113, in __call__
    await self.middleware_stack(scope, receive, send)
  File "C:\Users\llyn0\Desktop\Coding projects\WebDev2FinalProject\.venv312\Lib\site-packages\starlette\middleware\errors.py", line 186, in __call__     
    raise exc
  File "C:\Users\llyn0\Desktop\Coding projects\WebDev2FinalProject\.venv312\Lib\site-packages\starlette\middleware\errors.py", line 164, in __call__     
    await self.app(scope, receive, _send)
  File "C:\Users\llyn0\Desktop\Coding projects\WebDev2FinalProject\.venv312\Lib\site-packages\starlette\middleware\cors.py", line 93, in __call__        
    await self.simple_response(scope, receive, send, request_headers=headers)
  File "C:\Users\llyn0\Desktop\Coding projects\WebDev2FinalProject\.venv312\Lib\site-packages\starlette\middleware\cors.py", line 144, in simple_response
    await self.app(scope, receive, send)
  File "C:\Users\llyn0\Desktop\Coding projects\WebDev2FinalProject\.venv312\Lib\site-packages\starlette\middleware\exceptions.py", line 63, in __call__  
    await wrap_app_handling_exceptions(self.app, conn)(scope, receive, send)
  File "C:\Users\llyn0\Desktop\Coding projects\WebDev2FinalProject\.venv312\Lib\site-packages\starlette\_exception_handler.py", line 53, in wrapped_app  
    raise exc
  File "C:\Users\llyn0\Desktop\Coding projects\WebDev2FinalProject\.venv312\Lib\site-packages\starlette\_exception_handler.py", line 42, in wrapped_app  
    await app(scope, receive, sender)
  File "C:\Users\llyn0\Desktop\Coding projects\WebDev2FinalProject\.venv312\Lib\site-packages\fastapi\middleware\asyncexitstack.py", line 18, in __call__
    await self.app(scope, receive, send)
  File "C:\Users\llyn0\Desktop\Coding projects\WebDev2FinalProject\.venv312\Lib\site-packages\starlette\routing.py", line 716, in __call__
    await self.middleware_stack(scope, receive, send)
  File "C:\Users\llyn0\Desktop\Coding projects\WebDev2FinalProject\.venv312\Lib\site-packages\starlette\routing.py", line 736, in app
    await route.handle(scope, receive, send)
  File "C:\Users\llyn0\Desktop\Coding projects\WebDev2FinalProject\.venv312\Lib\site-packages\starlette\routing.py", line 290, in handle
    await self.app(scope, receive, send)
  File "C:\Users\llyn0\Desktop\Coding projects\WebDev2FinalProject\.venv312\Lib\site-packages\fastapi\routing.py", line 123, in app
    await wrap_app_handling_exceptions(app, request)(scope, receive, send)
  File "C:\Users\llyn0\Desktop\Coding projects\WebDev2FinalProject\.venv312\Lib\site-packages\starlette\_exception_handler.py", line 53, in wrapped_app  
    raise exc
  File "C:\Users\llyn0\Desktop\Coding projects\WebDev2FinalProject\.venv312\Lib\site-packages\starlette\_exception_handler.py", line 42, in wrapped_app  
    await app(scope, receive, sender)
  File "C:\Users\llyn0\Desktop\Coding projects\WebDev2FinalProject\.venv312\Lib\site-packages\fastapi\routing.py", line 109, in app
    response = await f(request)
               ^^^^^^^^^^^^^^^^
  File "C:\Users\llyn0\Desktop\Coding projects\WebDev2FinalProject\.venv312\Lib\site-packages\fastapi\routing.py", line 387, in app
    raw_response = await run_endpoint_function(
                   ^^^^^^^^^^^^^^^^^^^^^^^^^^^^
  File "C:\Users\llyn0\Desktop\Coding projects\WebDev2FinalProject\.venv312\Lib\site-packages\fastapi\routing.py", line 288, in run_endpoint_function    
    return await dependant.call(**values)
           ^^^^^^^^^^^^^^^^^^^^^^^^^^^^^^
  File "C:\Users\llyn0\Desktop\Coding projects\WebDev2FinalProject\backend\app\router\auth.py", line 37, in post_signup
    user = await User.create(
           ^^^^^^^^^^^^^^^^^^
  File "C:\Users\llyn0\Desktop\Coding projects\WebDev2FinalProject\.venv312\Lib\site-packages\tortoise\models.py", line 1138, in create
    db = using_db or cls._choose_db(True)
                     ^^^^^^^^^^^^^^^^^^^^
  File "C:\Users\llyn0\Desktop\Coding projects\WebDev2FinalProject\.venv312\Lib\site-packages\tortoise\models.py", line 1031, in _choose_db
    db = router.db_for_write(cls)
         ^^^^^^^^^^^^^^^^^^^^^^^^
  File "C:\Users\llyn0\Desktop\Coding projects\WebDev2FinalProject\.venv312\Lib\site-packages\tortoise\router.py", line 39, in db_for_write
    return self._db_route(model, "db_for_write")
           ^^^^^^^^^^^^^^^^^^^^^^^^^^^^^^^^^^^^^
  File "C:\Users\llyn0\Desktop\Coding projects\WebDev2FinalProject\.venv312\Lib\site-packages\tortoise\router.py", line 31, in _db_route
    return connections.get(self._router_func(model, action))
                           ^^^^^^^^^^^^^^^^^^^^^^^^^^^^^^^^
  File "C:\Users\llyn0\Desktop\Coding projects\WebDev2FinalProject\.venv312\Lib\site-packages\tortoise\router.py", line 18, in _router_func
    for r in self._routers:
TypeError: 'NoneType' object is not iterable
